Exception:
Traceback (most recent call last):
  File "/Library/Python/2.7/site-packages/pip/basecommand.py", line 139, in main
    status = self.run(options, args)
  File "/Library/Python/2.7/site-packages/pip/commands/install.py", line 235, in run
    InstallRequirement.from_line(name, None))
  File "/Library/Python/2.7/site-packages/pip/req.py", line 118, in from_line
    return cls(req, comes_from, url=url)
  File "/Library/Python/2.7/site-packages/pip/req.py", line 43, in __init__
    req = pkg_resources.Requirement.parse(req)
  File "/System/Library/Frameworks/Python.framework/Versions/2.7/Extras/lib/python/pkg_resources.py", line 2510, in parse
  File "/System/Library/Frameworks/Python.framework/Versions/2.7/Extras/lib/python/pkg_resources.py", line 2436, in parse_requirements
  File "/System/Library/Frameworks/Python.framework/Versions/2.7/Extras/lib/python/pkg_resources.py", line 2404, in scan_list
ValueError: ('Expected version spec in', 'django=', 'at', '=')

Storing complete log in /Users/davebridges/Library/Logs/pip.log
